[2017-04-04 13:07:58,198: INFO/MainProcess] Connected to amqp://guest:**@127.0.0.1:5672//
[2017-04-04 13:07:58,209: INFO/MainProcess] mingle: searching for neighbors
[2017-04-04 13:07:59,230: INFO/MainProcess] mingle: all alone
[2017-04-04 13:07:59,243: WARNING/MainProcess] /usr/lib64/python2.7/site-packages/celery/fixups/django.py:202: UserWarning: Using settings.DEBUG leads to a memory leak, never use this setting in production environments!
  warnings.warn('Using settings.DEBUG leads to a memory leak, never '
[2017-04-04 13:07:59,243: INFO/MainProcess] celery@sec-tools-02 ready.
[2017-04-04 13:08:16,634: INFO/MainProcess] Received task: scans.tasks.delegate[ffa934ce-789d-469c-a87d-07d412e55c50]  
[2017-04-04 13:08:16,635: INFO/MainProcess] Received task: scans.tasks.delegate[97d976e1-0609-476e-a8ed-45b0b0e64c02]  
[04/Apr/2017 13:08:17] ERROR [scarab:108] Scan: http://scanme.nmap.org, Tool: ArachniGauntlt <class 'plugins.gauntlt.GauntltArachni'>, Class: <class 'plugins.gauntlt.GauntltArachni'>, Other: [Errno 17] File exists: '/home/djayasankar/Documents/webscanner/temporary/G3pfYwRqjQ'
[2017-04-04 13:08:17,276: ERROR/PoolWorker-23] Scan: http://scanme.nmap.org, Tool: ArachniGauntlt <class 'plugins.gauntlt.GauntltArachni'>, Class: <class 'plugins.gauntlt.GauntltArachni'>, Other: [Errno 17] File exists: '/home/djayasankar/Documents/webscanner/temporary/G3pfYwRqjQ'
[2017-04-04 13:08:17,278: ERROR/PoolWorker-23] Task scans.tasks.delegate[97d976e1-0609-476e-a8ed-45b0b0e64c02] raised unexpected: NameError("global name 'PassFailTool' is not defined",)
Traceback (most recent call last):
  File "/usr/lib64/python2.7/site-packages/celery/app/trace.py", line 367, in trace_task
    R = retval = fun(*args, **kwargs)
  File "/usr/lib64/python2.7/site-packages/celery/app/trace.py", line 622, in __protected_call__
    return self.run(*args, **kwargs)
  File "/home/djayasankar/Documents/webscanner/scans/tasks.py", line 32, in delegate
    instance = plugin(model_pk=int(model_id))
  File "/home/djayasankar/Documents/webscanner/plugins/gauntlt.py", line 15, in __init__
    self.do_configure()
  File "/home/djayasankar/Documents/webscanner/plugins/gauntlt.py", line 18, in do_configure
    super(GauntltArachni, self).do_configure()
  File "/home/djayasankar/Documents/webscanner/webscanner/plugin_api.py", line 165, in do_configure
    special_tool = PassFailTool(tool_ptr_id=self.tool.id)
NameError: global name 'PassFailTool' is not defined
[2017-04-04 13:08:23,415: ERROR/PoolWorker-18] Chord callback for 'd67c41b3-f05d-43d7-aae9-996c871e7695' raised: ChordError(u'Dependency 97d976e1-0609-476e-a8ed-45b0b0e64c02 raised NameError("global name \'PassFailTool\' is not defined",)',)
Traceback (most recent call last):
  File "/usr/lib64/python2.7/site-packages/celery/backends/redis.py", line 281, in on_chord_part_return
    callback.delay([unpack(tup, decode) for tup in resl])
  File "/usr/lib64/python2.7/site-packages/celery/backends/redis.py", line 234, in _unpack_chord_result
    raise ChordError('Dependency {0} raised {1!r}'.format(tid, retval))
ChordError: Dependency 97d976e1-0609-476e-a8ed-45b0b0e64c02 raised NameError("global name 'PassFailTool' is not defined",)
[2017-04-04 13:08:23,417: INFO/PoolWorker-18] Task scans.tasks.delegate[ffa934ce-789d-469c-a87d-07d412e55c50] succeeded in 6.15913096536s: {'W3af': {'files': [(...), (...), (...), (...)]}}
